Workbook

Sheet Overview
A1: Investment Analyst Case Study Fall 2025
A4: Overview:
A5: You are evaluating two potential investment funds for inclusion in a portfolio with the following equally weighted objectives: - Generate long-term annualized returns in at least the high single digits - Preserve capital and minimize the risk of impairment - Offer strong diversification from public equities Return data for both funds is provided on the following tabs of this workbook. 1. Hedge Fund 1: event driven credit strategy 2. Hedge Fund 2: systematic global macro strategy Please evaluate each fund relative to the objectives listed above and provide a written response as described below:
A6: Written response:
A7: For each fund, create a separate Word document that includes written responses to the following three questions: 1. What stands out to you in your evaluation of the fund, specifically in relation to the portfolio’s three objectives? 2. Would you recommend further due diligence? Clearly state yes or no. Provide a brief explanation of your reasoning 3. What additional information would be helpful to complete your evaluation of the fund?

Sheet Hedge Fund 1
A2: -Hedge Fund 1 is their firm's flagship strategy and has been running since 1991 -Hedge Fund 1 has a total AUM of ~$55B and the firm manages ~$100B in total -The firm employs ~1,200 professionals of which ~500 are Investment staff -AUM and employee count have each come down in recent years as part of a broader initiative to improve returns and accountability -The founder of the firm has recently stepped down from his roles as CEO and Co-Chief Investment Officer
A12: -The Fund is designed as a systematic alpha strategy and seeks to have no reliance on beta -The Fund is fundamental in research and systematic in implemention (model driven rather than left to human discretion) -More than 200 models filter economic data to produce indicators on positions which are then funneled through an optimizer to establish sizing and eventual portfolio construction

Sheet Hedge Fund 2
A1: Firm and Team Overview
A2: -The Firm was founded in 2001, and Hedge Fund 2 was launhed in 2012 as the Firm's second standalone strategy. -Hedge Fund 2 has a NAV of $650mm, with the top 2 investors accounting for over 80% of invested capital. -The Fund is run by a single Portfolio Manager and a team of 4 analysts. -The Fund has not raised any meaningful capital in over 10 years. -Two years ago, the entire analyst team was let go or left the firm. The Portfolio Manager subsequently restaffed the team with more junior analysts.
A11: Strategy Overview
A12: -The Fund pursues an event driven strategy focused on credit special situations and distressed debt. -The portfolio is fairly concentrated with the top 10 positions typically accounting for well over 60% of NAV. -The team will take an active role in situations by participating in creditor committees or through structuring unique transactions. -The Portfolio Manager likes very assymetric trades where the upside to downside of a deal is typicall 4:1.

Sheet Return Data
B1: Hedge Fund 1 | C1: Hedge Fund 2 | H1: S&P_500
A2: 42035 | B2: 0.0755 | C2: -0.0077 | H2: -0.031
A3: 42063 | B3: 0.0276 | C3: 0.0268 | H3: 0.054
A4: 42094 | B4: 0.0306 | C4: -0.0009 | H4: -0.017396107
A5: 42124 | B5: -0.0103 | C5: 0.0085 | H5: 0.0085208198
A6: 42155 | B6: 0.0167 | C6: 0.0115 | H6: 0.010491382
A7: 42185 | B7: -0.0334 | C7: -0.0239 | H7: -0.021011672
A8: 42216 | B8: 0.0104 | C8: -0.0198 | H8: 0.019742029
A9: 42247 | B9: -0.0563 | C9: -0.0044 | H9: -0.062580818
A10: 42277 | B10: -0.0003 | C10: -0.0091 | H10: -0.026442831
A11: 42308 | B11: 0.0279 | C11: 0.0127 | H11: 0.082983118
A12: 42338 | B12: 0.0101 | C12: -0.0036 | H12: 0.00050486911
A13: 42369 | B13: -0.0293 | C13: -0.0102 | H13: -0.017530185
... A129: 45900 | B129: 0.0303 | C129: 0.0019 | H129: 0.019066444

Sheet Disclaimer
B3: Disclaimer:
B4: All analysis, calculations, and written interpretations in this report are my original work.
B5: Monthly S&P 500 returns for the 2015–2025 period were obtained using Python through the yfinance library to ensure data accuracy and consistency.
B6: A constant annualized risk-free rate of 2% was assumed for all Sharpe ratio and performance-related computations.
B7: All intuition, reasoning, and conclusions reflect my own independent thinking, grounded in personal learning, academic coursework, and professional education.
B8: Grammarly was used for spelling check.

Sheet WorkBook
B1: Fund1_Cumulative | C1: Fund2_Cumulative | D1: Fund1_Drawdown | E1: Fund2_Drawdown | F1: S&P_500 | H1: Fund1_RollAnn_12m | I1: Fund2_RollAnn_12m | J1: Target 8% (High Single Digits) | K1: Fund1_Roll_Vol_12m | L1: Fund2_Roll_Vol_12m | M1: Fund1_Roll_Sharpe_Ratio | N1: Fund2_Roll_Sharpe_Ratio | Q1: Lag 1 | R1: Rolling Autocorr 12m | T1: Lag 1 | U1: Rolling Autocorr 12m | W1: UnderWater Flag HF1 | X1: UnderWater Flag HF2 | Y1: Streak Counter 1 | Z1: Streak Counter 2 | AB1: HF1_Roll_12m_Corr_w_S&P500 | AC1: HF2_Roll_12m_Corr_w_S&P501 | AE1: SP500_Down <0 | AF1: HF1_Down | AG1: HF2_Down | AI1: SP500_Down | AJ1: HF1_Down | AK1: HF1_Down
A2: 42035 | B2: =1+'Return Data'!B2 -> 1.0755 | C2: =1+'Return Data'!C2 -> 0.9923 | D2: =B2/MAX($B$2:B2)-1 -> 0 | E2: =C2/MAX($C$2:C2)-1 -> 0 | F2: -0.031 | J2: 0.08 | W2: =IF(D2<0,1,0) -> 0 | X2: =IF(E2<0,1,0) -> 0 | Y2: 0 | Z2: 0 | AE2: =IF($F2<0,$F2,"") -> -0.031 | AF2: =IF($F2<0,'Return Data'!B2,"") -> 0.0755 | AG2: =IF($F2<0,'Return Data'!C2,"") -> -0.0077 | AI2: =AE2 -> -0.031 | AJ2: =AF2 -> 0.0755 | AK2: =AG2 -> -0.0077
A3: 42063 | B3: =B2*(1+'Return Data'!B3) -> 1.1051838 | C3: =C2*(1+'Return Data'!C3) -> 1.0188936 | D3: =B3/MAX($B$2:B3)-1 -> 0 | E3: =C3/MAX($C$2:C3)-1 -> 0 | F3: 0.054 | J3: 0.08 | Q3: =OFFSET('Return Data'!B3,-1,0) -> 0.0755 | T3: =OFFSET('Return Data'!C3,-1,0) -> -0.0077 | W3: =IF(D3<0,1,0) -> 0 | X3: =IF(E3<0,1,0) -> 0 | Y3: =IF(W3=1, IF(W2=0, Y2+1, Y2), Y2) -> 0 | Z3: =IF(X3=1, IF(X2=0, Z2+1, Z2), Z2) -> 0 | AE3: =IF($F3<0,$F3,"") | AF3: =IF($F3<0,'Return Data'!B3,"") | AG3: =IF($F3<0,'Return Data'!C3,"") | AI3: =AE4 -> -0.017396107 | AJ3: =AF4 -> 0.0306 | AK3: =AG4 -> -0.0009
A4: 42094 | B4: =B3*(1+'Return Data'!B4) -> 1.1390024 | C4: =C3*(1+'Return Data'!C4) -> 1.0179766 | D4: =B4/MAX($B$2:B4)-1 -> 0 | E4: =C4/MAX($C$2:C4)-1 -> -0.0009 | F4: -0.017396107 | J4: 0.08 | Q4: =OFFSET('Return Data'!B4,-1,0) -> 0.0276 | T4: =OFFSET('Return Data'!C4,-1,0) -> 0.0268 | W4: =IF(D4<0,1,0) -> 0 | X4: =IF(E4<0,1,0) -> 1 | Y4: =IF(W4=1, IF(W3=0, Y3+1, Y3), Y3) -> 0 | Z4: =IF(X4=1, IF(X3=0, Z3+1, Z3), Z3) -> 1 | AE4: =IF($F4<0,$F4,"") -> -0.017396107 | AF4: =IF($F4<0,'Return Data'!B4,"") -> 0.0306 | AG4: =IF($F4<0,'Return Data'!C4,"") -> -0.0009 | AI4: =AE7 -> -0.021011672 | AJ4: =AF4 -> 0.0306 | AK4: =AG4 -> -0.0009
A5: 42124 | B5: =B4*(1+'Return Data'!B5) -> 1.1272707 | C5: =C4*(1+'Return Data'!C5) -> 1.0266294 | D5: =B5/MAX($B$2:B5)-1 -> -0.0103 | E5: =C5/MAX($C$2:C5)-1 -> 0 | F5: 0.0085208198 | J5: 0.08 | O5: rf | P5: 0.02 | Q5: =OFFSET('Return Data'!B5,-1,0) -> 0.0306 | T5: =OFFSET('Return Data'!C5,-1,0) -> -0.0009 | W5: =IF(D5<0,1,0) -> 1 | X5: =IF(E5<0,1,0) -> 0 | Y5: =IF(W5=1, IF(W4=0, Y4+1, Y4), Y4) -> 1 | Z5: =IF(X5=1, IF(X4=0, Z4+1, Z4), Z4) -> 1 | AE5: =IF($F5<0,$F5,"") | AF5: =IF($F5<0,'Return Data'!B5,"") | AG5: =IF($F5<0,'Return Data'!C5,"") | AI5: =AE9 -> -0.062580818 | AJ5: =AF9 -> -0.0563 | AK5: =AG9 -> -0.0044 | AP5: Hypothesis 2
A6: 42155 | B6: =B5*(1+'Return Data'!B6) -> 1.1460961 | C6: =C5*(1+'Return Data'!C6) -> 1.0384357 | D6: =B6/MAX($B$2:B6)-1 -> 0 | E6: =C6/MAX($C$2:C6)-1 -> 0 | F6: 0.010491382 | J6: 0.08 | Q6: =OFFSET('Return Data'!B6,-1,0) -> -0.0103 | T6: =OFFSET('Return Data'!C6,-1,0) -> 0.0085 | W6: =IF(D6<0,1,0) -> 0 | X6: =IF(E6<0,1,0) -> 0 | Y6: =IF(W6=1, IF(W5=0, Y5+1, Y5), Y5) -> 1 | Z6: =IF(X6=1, IF(X5=0, Z5+1, Z5), Z5) -> 1 | AE6: =IF($F6<0,$F6,"") | AF6: =IF($F6<0,'Return Data'!B6,"") | AG6: =IF($F6<0,'Return Data'!C6,"") | AI6: =AE10 -> -0.026442831 | AJ6: =AF10 -> -0.0003 | AK6: =AG10 -> -0.0091 | AR6: Hedge Fund 1 | AS6: Hedge Fund 2
A7: 42185 | B7: =B6*(1+'Return Data'!B7) -> 1.1078165 | C7: =C6*(1+'Return Data'!C7) -> 1.0136171 | D7: =B7/MAX($B$2:B7)-1 -> -0.0334 | E7: =C7/MAX($C$2:C7)-1 -> -0.0239 | F7: -0.021011672 | J7: 0.08 | Q7: =OFFSET('Return Data'!B7,-1,0) -> 0.0167 | T7: =OFFSET('Return Data'!C7,-1,0) -> 0.0115 | W7: =IF(D7<0,1,0) -> 1 | X7: =IF(E7<0,1,0) -> 1 | Y7: =IF(W7=1, IF(W6=0, Y6+1, Y6), Y6) -> 2 | Z7: =IF(X7=1, IF(X6=0, Z6+1, Z6), Z6) -> 2 | AE7: =IF($F7<0,$F7,"") -> -0.021011672 | AF7: =IF($F7<0,'Return Data'!B7,"") -> -0.0334 | AG7: =IF($F7<0,'Return Data'!C7,"") -> -0.0239 | AI7: =AE13 -> -0.017530185 | AJ7: =AF13 -> -0.0293 | AK7: =AG13 -> -0.0102 | AP7: Depth of worst loss | AQ7: Maximum Drawdown (MDD) | AR7: =MIN(D2:D129) -> -0.233163 | AS7: =MIN(E2:E129) -> -0.1512069
A8: 42216 | B8: =B7*(1+'Return Data'!B8) -> 1.1193378 | C8: =C7*(1+'Return Data'!C8) -> 0.99354745 | D8: =B8/MAX($B$2:B8)-1 -> -0.02334736 | E8: =C8/MAX($C$2:C8)-1 -> -0.04322678 | F8: 0.019742029 | J8: 0.08 | Q8: =OFFSET('Return Data'!B8,-1,0) -> -0.0334 | T8: =OFFSET('Return Data'!C8,-1,0) -> -0.0239 | W8: =IF(D8<0,1,0) -> 1 | X8: =IF(E8<0,1,0) -> 1 | Y8: =IF(W8=1, IF(W7=0, Y7+1, Y7), Y7) -> 2 | Z8: =IF(X8=1, IF(X7=0, Z7+1, Z7), Z7) -> 2 | AE8: =IF($F8<0,$F8,"") | AF8: =IF($F8<0,'Return Data'!B8,"") | AG8: =IF($F8<0,'Return Data'!C8,"") | AI8: =AE14 -> -0.050735322 | AJ8: =AF14 -> 0.007 | AK8: =AG14 -> -0.0066 | AQ8: Average Annualized Return | AR8: =AVERAGE(H2:H129) -> 0.054434931 | AS8: =AVERAGE(I2:I129) -> 0.096126043
A9: 42247 | B9: =B8*(1+'Return Data'!B9) -> 1.0563191 | C9: =C8*(1+'Return Data'!C9) -> 0.98917584 | D9: =B9/MAX($B$2:B9)-1 -> -0.078332904 | E9: =C9/MAX($C$2:C9)-1 -> -0.047436582 | F9: -0.062580818 | J9: 0.08 | Q9: =OFFSET('Return Data'!B9,-1,0) -> 0.0104 | T9: =OFFSET('Return Data'!C9,-1,0) -> -0.0198 | W9: =IF(D9<0,1,0) -> 1 | X9: =IF(E9<0,1,0) -> 1 | Y9: =IF(W9=1, IF(W8=0, Y8+1, Y8), Y8) -> 2 | Z9: =IF(X9=1, IF(X8=0, Z8+1, Z8), Z8) -> 2 | AE9: =IF($F9<0,$F9,"") -> -0.062580818 | AF9: =IF($F9<0,'Return Data'!B9,"") -> -0.0563 | AG9: =IF($F9<0,'Return Data'!C9,"") -> -0.0044 | AI9: =AE15 -> -0.0041283603 | AJ9: =AF15 -> -0.0577 | AK9: =AG15 -> -0.0115 | AP9: Time underwater | AQ9: Average Drawdown Duration | AR9: {=AVERAGE( IF(FREQUENCY(IF(W2:W128=1,ROW(W2:W128)), IF(W2:W128=0,ROW(W2:W128)))>0,FREQUENCY(IF(W2:W128=1,ROW(W2:W128)), IF(W2:W128=0,ROW(W2:W128)))))} -> 8.8333333 | AS9: {=AVERAGE( IF(FREQUENCY(IF(X2:X128=1,ROW(X2:X128)), IF(X2:X128=0,ROW(X2:X128)))>0,FREQUENCY(IF(X2:X128=1,ROW(X2:X128)), IF(X2:X128=0,ROW(X2:X128)))))} -> 5.2307692
A10: 42277 | B10: =B9*(1+'Return Data'!B10) -> 1.0560022 | C10: =C9*(1+'Return Data'!C10) -> 0.98017434 | D10: =B10/MAX($B$2:B10)-1 -> -0.078609404 | E10: =C10/MAX($C$2:C10)-1 -> -0.056104909 | F10: -0.026442831 | J10: 0.08 | Q10: =OFFSET('Return Data'!B10,-1,0) -> -0.0563 | T10: =OFFSET('Return Data'!C10,-1,0) -> -0.0044 | W10: =IF(D10<0,1,0) -> 1 | X10: =IF(E10<0,1,0) -> 1 | Y10: =IF(W10=1, IF(W9=0, Y9+1, Y9), Y9) -> 2 | Z10: =IF(X10=1, IF(X9=0, Z9+1, Z9), Z9) -> 2 | AE10: =IF($F10<0,$F10,"") -> -0.026442831 | AF10: =IF($F10<0,'Return Data'!B10,"") -> -0.0003 | AG10: =IF($F10<0,'Return Data'!C10,"") -> -0.0091 | AI10: =AE21 -> -0.0012192429 | AJ10: =AF21 -> 0.0111 | AK10: =AG21 -> 0.0025 | AP10: Recovery Efficiency | AQ10: MAR Ratio ( Return / Max Drawdown ) | AR10: =AR8/ABS(AR7) -> 0.23346299 | AS10: =AS8/ABS(AS7) -> 0.63572524
A11: 42308 | B11: =B10*(1+'Return Data'!B11) -> 1.0854646 | C11: =C10*(1+'Return Data'!C11) -> 0.99262255 | D11: =B11/MAX($B$2:B11)-1 -> -0.052902606 | E11: =C11/MAX($C$2:C11)-1 -> -0.044117442 | F11: 0.082983118 | J11: 0.08 | Q11: =OFFSET('Return Data'!B11,-1,0) -> -0.0003 | T11: =OFFSET('Return Data'!C11,-1,0) -> -0.0091 | W11: =IF(D11<0,1,0) -> 1 | X11: =IF(E11<0,1,0) -> 1 | Y11: =IF(W11=1, IF(W10=0, Y10+1, Y10), Y10) -> 2 | Z11: =IF(X11=1, IF(X10=0, Z10+1, Z10), Z10) -> 2 | AE11: =IF($F11<0,$F11,"") | AF11: =IF($F11<0,'Return Data'!B11,"") | AG11: =IF($F11<0,'Return Data'!C11,"") | AI11: =AE22 -> -0.0012344511 | AJ11: =AF22 -> 0.0056 | AK11: =AG22 -> 0.0045 | AP11: How deep and persistent drawdowns are | AQ11: Ulcer Index (UI) | AR11: {=SQRT(SUMPRODUCT(D2:D128*D2:D128)/COUNT(D2:D128))} -> 0.094449932 | AS11: {=SQRT(SUMPRODUCT(E2:E128*E2:E128)/COUNT(E2:E128))} -> 0.03242902
A12: 42338 | B12: =B11*(1+'Return Data'!B12) -> 1.0964278 | C12: =C11*(1+'Return Data'!C12) -> 0.98904911 | D12: =B12/MAX($B$2:B12)-1 -> -0.043336922 | E12: =C12/MAX($C$2:C12)-1 -> -0.047558619 | F12: 0.00050486911 | J12: 0.08 | Q12: =OFFSET('Return Data'!B12,-1,0) -> 0.0279 | T12: =OFFSET('Return Data'!C12,-1,0) -> 0.0127 | W12: =IF(D12<0,1,0) -> 1 | X12: =IF(E12<0,1,0) -> 1 | Y12: =IF(W12=1, IF(W11=0, Y11+1, Y11), Y11) -> 2 | Z12: =IF(X12=1, IF(X11=0, Z11+1, Z11), Z11) -> 2 | AE12: =IF($F12<0,$F12,"") | AF12: =IF($F12<0,'Return Data'!B12,"") | AG12: =IF($F12<0,'Return Data'!C12,"") | AI12: =AE23 -> -0.019425679 | AJ12: =AF23 -> 0.0889 | AK12: =AG23 -> 0.0172
A13: 42369 | B13: =B12*(1+'Return Data'!B13) -> 1.0643025 | C13: =C12*(1+'Return Data'!C13) -> 0.97896081 | D13: =B13/MAX($B$2:B13)-1 -> -0.071367151 | E13: =C13/MAX($C$2:C13)-1 -> -0.057273521 | F13: -0.017530185 | H13: {=PRODUCT(1+'Return Data'!B2:B13)^(12/COUNT('Return Data'!B2:B13))-1} -> 0.064302506 | I13: {=PRODUCT(1+'Return Data'!C2:C13)^(12/COUNT('Return Data'!C2:C13))-1} -> -0.021039192 | J13: 0.08 | K13: =_xlfn.STDEV.S('Return Data'!B2:B13)*SQRT(12) -> 0.12143104 | L13: =_xlfn.STDEV.S('Return Data'!C2:C13)*SQRT(12) -> 0.050013262 | M13: =(H13-$P$5)/K13 -> 0.36483674 | N13: =(I13-$P$5)/L13 -> -0.82056619 | Q13: =OFFSET('Return Data'!B13,-1,0) -> 0.0101 | R13: =CORREL('Return Data'!B2:B13,WorkBook!Q2:Q13) -> 0.10013941 | T13: =OFFSET('Return Data'!C13,-1,0) -> -0.0036 | U13: =CORREL('Return Data'!C2:C13,WorkBook!T2:T13) -> 0.022128166 | W13: =IF(D13<0,1,0) -> 1 | X13: =IF(E13<0,1,0) -> 1 | Y13: =IF(W13=1, IF(W12=0, Y12+1, Y12), Y12) -> 2 | Z13: =IF(X13=1, IF(X12=0, Z12+1, Z12), Z12) -> 2 | AB13: =IFERROR(CORREL(H2:H13,$F$2:$F$13), "") | AC13: =IFERROR(CORREL(I2:I13,$F$2:$F$13), "") | AE13: =IF($F13<0,$F13,"") -> -0.017530185 | AF13: =IF($F13<0,'Return Data'!B13,"") -> -0.0293 | AG13: =IF($F13<0,'Return Data'!C13,"") -> -0.0102 | AI13: =AE28 -> -0.00038919714 | AJ13: =AF28 -> 0.0179 | AK13: =AG28 -> -0.0009
A14: 42400 | B14: =B13*(1+'Return Data'!B14) -> 1.0717526 | C14: =C13*(1+'Return Data'!C14) -> 0.97249967 | D14: =B14/MAX($B$2:B14)-1 -> -0.064866721 | E14: =C14/MAX($C$2:C14)-1 -> -0.063495516 | F14: -0.050735322 | H14: {=PRODUCT(1+'Return Data'!B3:B14)^(12/COUNT('Return Data'!B3:B14))-1} -> -0.0034843114 | I14: {=PRODUCT(1+'Return Data'!C3:C14)^(12/COUNT('Return Data'!C3:C14))-1} -> -0.019953979 | J14: 0.08 | K14: =_xlfn.STDEV.S('Return Data'!B3:B14)*SQRT(12) -> 0.094951485 | L14: =_xlfn.STDEV.S('Return Data'!C3:C14)*SQRT(12) -> 0.049880621 | M14: =(H14-$P$5)/K14 -> -0.24732958 | N14: =(I14-$P$5)/L14 -> -0.800992 | Q14: =OFFSET('Return Data'!B14,-1,0) -> -0.0293 | R14: =CORREL('Return Data'!B3:B14,WorkBook!Q3:Q14) -> 0.069612834 | T14: =OFFSET('Return Data'!C14,-1,0) -> -0.0102 | U14: =CORREL('Return Data'!C3:C14,WorkBook!T3:T14) -> 0.042012828 | W14: =IF(D14<0,1,0) -> 1 | X14: =IF(E14<0,1,0) -> 1 | Y14: =IF(W14=1, IF(W13=0, Y13+1, Y13), Y13) -> 2 | Z14: =IF(X14=1, IF(X13=0, Z13+1, Z13), Z13) -> 2 | AB14: =CORREL(H3:H14,$F$2:$F$13) -> 1 | AC14: =CORREL(I3:I14,$F$2:$F$13) -> -1 | AE14: =IF($F14<0,$F14,"") -> -0.050735322 | AF14: =IF($F14<0,'Return Data'!B14,"") -> 0.007 | AG14: =IF($F14<0,'Return Data'!C14,"") -> -0.0066 | AI14: =AE39 -> -0.038947372 | AJ14: =AF39 -> 0.0183 | AK14: =AG39 -> 0.0037
A15: 42429 | B15: =B14*(1+'Return Data'!B15) -> 1.0099125 | C15: =C14*(1+'Return Data'!C15) -> 0.96131592 | D15: =B15/MAX($B$2:B15)-1 -> -0.11882391 | E15: =C15/MAX($C$2:C15)-1 -> -0.074265317 | F15: -0.0041283603 | H15: {=PRODUCT(1+'Return Data'!B4:B15)^(12/COUNT('Return Data'!B4:B15))-1} -> -0.086204035 | I15: {=PRODUCT(1+'Return Data'!C4:C15)^(12/COUNT('Return Data'!C4:C15))-1} -> -0.056510039 | J15: 0.08 | K15: =_xlfn.STDEV.S('Return Data'!B4:B15)*SQRT(12) -> 0.10566986 | L15: =_xlfn.STDEV.S('Return Data'!C4:C15)*SQRT(12) -> 0.03978884 | M15: =(H15-$P$5)/K15 -> -1.0050551 | N15: =(I15-$P$5)/L15 -> -1.922902 | Q15: =OFFSET('Return Data'!B15,-1,0) -> 0.007 | R15: =CORREL('Return Data'!B4:B15,WorkBook!Q4:Q15) -> -0.18950768 | T15: =OFFSET('Return Data'!C15,-1,0) -> -0.0066 | U15: =CORREL('Return Data'!C4:C15,WorkBook!T4:T15) -> 0.17558116 | W15: =IF(D15<0,1,0) -> 1 | X15: =IF(E15<0,1,0) -> 1 | Y15: =IF(W15=1, IF(W14=0, Y14+1, Y14), Y14) -> 2 | Z15: =IF(X15=1, IF(X14=0, Z14+1, Z14), Z14) -> 2 | AB15: =CORREL(H4:H15,$F$2:$F$13) -> 0.91642425 | AC15: =CORREL(I4:I15,$F$2:$F$13) -> 0.61830472 | AE15: =IF($F15<0,$F15,"") -> -0.0041283603 | AF15: =IF($F15<0,'Return Data'!B15,"") -> -0.0577 | AG15: =IF($F15<0,'Return Data'!C15,"") -> -0.0115 | AI15: =AE40 -> -0.026884499 | AJ15: =AF40 -> -0.0164 | AK15: =AG40 -> -0.0173
A16: 42460 | B16: =B15*(1+'Return Data'!B16) -> 0.99203705 | C16: =C15*(1+'Return Data'!C16) -> 0.99428906 | D16: =B16/MAX($B$2:B16)-1 -> -0.13442073 | E16: =C16/MAX($C$2:C16)-1 -> -0.042512618 | F16: 0.065991114 | H16: {=PRODUCT(1+'Return Data'!B5:B16)^(12/COUNT('Return Data'!B5:B16))-1} -> -0.12902991 | I16: {=PRODUCT(1+'Return Data'!C5:C16)^(12/COUNT('Return Data'!C5:C16))-1} -> -0.023269276 | J16: 0.08 | K16: =_xlfn.STDEV.S('Return Data'!B5:B16)*SQRT(12) -> 0.09762881 | L16: =_xlfn.STDEV.S('Return Data'!C5:C16)*SQRT(12) -> 0.055855097 | M16: =(H16-$P$5)/K16 -> -1.5264952 | N16: =(I16-$P$5)/L16 -> -0.77467014 | Q16: =OFFSET('Return Data'!B16,-1,0) -> -0.0577 | R16: =CORREL('Return Data'!B5:B16,WorkBook!Q5:Q16) -> -0.26522142 | T16: =OFFSET('Return Data'!C16,-1,0) -> -0.0115 | U16: =CORREL('Return Data'!C5:C16,WorkBook!T5:T16) -> -0.032248782 | W16: =IF(D16<0,1,0) -> 1 | X16: =IF(E16<0,1,0) -> 1 | Y16: =IF(W16=1, IF(W15=0, Y15+1, Y15), Y15) -> 2 | Z16: =IF(X16=1, IF(X15=0, Z15+1, Z15), Z15) -> 2 | AB16: =CORREL(H5:H16,$F$2:$F$13) -> 0.13573476 | AC16: =CORREL(I5:I16,$F$2:$F$13) -> 0.17913125 | AE16: =IF($F16<0,$F16,"") | AF16: =IF($F16<0,'Return Data'!B16,"") | AG16: =IF($F16<0,'Return Data'!C16,"") | AI16: =AE47 -> -0.069403356 | AJ16: =AF47 -> 0.0487 | AK16: =AG47 -> 0.0024
A17: 42490 | B17: =B16*(1+'Return Data'!B17) -> 0.9721963 | C17: =C16*(1+'Return Data'!C17) -> 1.0126834 | D17: =B17/MAX($B$2:B17)-1 -> -0.15173231 | E17: =C17/MAX($C$2:C17)-1 -> -0.024799101 | F17: 0.0026993983 | H17: {=PRODUCT(1+'Return Data'!B6:B17)^(12/COUNT('Return Data'!B6:B17))-1} -> -0.13756624 | I17: {=PRODUCT(1+'Return Data'!C6:C17)^(12/COUNT('Return Data'!C6:C17))-1} -> -0.013584291 | J17: 0.08 | K17: =_xlfn.STDEV.S('Return Data'!B6:B17)*SQRT(12) -> 0.098025878 | L17: =_xlfn.STDEV.S('Return Data'!C6:C17)*SQRT(12) -> 0.05869777 | M17: =(H17-$P$5)/K17 -> -1.6073944 | N17: =(I17-$P$5)/L17 -> -0.57215616 | Q17: =OFFSET('Return Data'!B17,-1,0) -> -0.0177 | R17: =CORREL('Return Data'!B6:B17,WorkBook!Q6:Q17) -> -0.28284482 | T17: =OFFSET('Return Data'!C17,-1,0) -> 0.0343 | U17: =CORREL('Return Data'!C6:C17,WorkBook!T6:T17) -> 0.21952339 | W17: =IF(D17<0,1,0) -> 1 | X17: =IF(E17<0,1,0) -> 1 | Y17: =IF(W17=1, IF(W16=0, Y16+1, Y16), Y16) -> 2 | Z17: =IF(X17=1, IF(X16=0, Z16+1, Z16), Z16) -> 2 | AB17: =CORREL(H6:H17,$F$2:$F$13) -> -0.53738282 | AC17: =CORREL(I6:I17,$F$2:$F$13) -> -0.8828362 | AE17: =IF($F17<0,$F17,"") | AF17: =IF($F17<0,'Return Data'!B17,"") | AG17: =IF($F17<0,'Return Data'!C17,"") | AI17: =AE49 -> -0.091776895 | AJ17: =AF49 -> 0.073 | AK17: =AG49 -> -0.001
A18: 42521 | B18: =B17*(1+'Return Data'!B18) -> 0.97141855 | C18: =C17*(1+'Return Data'!C18) -> 1.0103542 | D18: =B18/MAX($B$2:B18)-1 -> -0.15241093 | E18: =C18/MAX($C$2:C18)-1 -> -0.027042063 | F18: 0.015324603 | H18: {=PRODUCT(1+'Return Data'!B7:B18)^(12/COUNT('Return Data'!B7:B18))-1} -> -0.15241093 | I18: {=PRODUCT(1+'Return Data'!C7:C18)^(12/COUNT('Return Data'!C7:C18))-1} -> -0.027042063 | J18: 0.08 | K18: =_xlfn.STDEV.S('Return Data'!B7:B18)*SQRT(12) -> 0.093935931 | L18: =_xlfn.STDEV.S('Return Data'!C7:C18)*SQRT(12) -> 0.057089873 | M18: =(H18-$P$5)/K18 -> -1.8354098 | N18: =(I18-$P$5)/L18 -> -0.82400013 | Q18: =OFFSET('Return Data'!B18,-1,0) -> -0.02 | R18: =CORREL('Return Data'!B7:B18,WorkBook!Q7:Q18) -> -0.30998363 | T18: =OFFSET('Return Data'!C18,-1,0) -> 0.0185 | U18: =CORREL('Return Data'!C7:C18,WorkBook!T7:T18) -> 0.1678544 | W18: =IF(D18<0,1,0) -> 1 | X18: =IF(E18<0,1,0) -> 1 | Y18: =IF(W18=1, IF(W17=0, Y17+1, Y17), Y17) -> 2 | Z18: =IF(X18=1, IF(X17=0, Z17+1, Z17), Z17) -> 2 | AB18: =CORREL(H7:H18,$F$2:$F$13) -> -0.21444132 | AC18: =CORREL(I7:I18,$F$2:$F$13) -> 0.20680618 | AE18: =IF($F18<0,$F18,"") | AF18: =IF($F18<0,'Return Data'!B18,"") | AG18: =IF($F18<0,'Return Data'!C18,"") | AI18: =AE54 -> -0.065777731 | AJ18: =AF54 -> -0.0334 | AK18: =AG54 -> -0.018
A19: 42551 | B19: =B18*(1+'Return Data'!B19) -> 0.94247027 | C19: =C18*(1+'Return Data'!C19) -> 1.021165 | D19: =B19/MAX($B$2:B19)-1 -> -0.17766908 | E19: =C19/MAX($C$2:C19)-1 -> -0.016631413 | F19: 0.00091092124 | H19: {=PRODUCT(1+'Return Data'!B8:B19)^(12/COUNT('Return Data'!B8:B19))-1} -> -0.14925417 | I19: {=PRODUCT(1+'Return Data'!C8:C19)^(12/COUNT('Return Data'!C8:C19))-1} -> 0.0074465596 | J19: 0.08 | K19: =_xlfn.STDEV.S('Return Data'!B8:B19)*SQRT(12) -> 0.093163136 | L19: =_xlfn.STDEV.S('Return Data'!C8:C19)*SQRT(12) -> 0.053057662 | M19: =(H19-$P$5)/K19 -> -1.8167505 | N19: =(I19-$P$5)/L19 -> -0.23659996 | Q19: =OFFSET('Return Data'!B19,-1,0) -> -0.0008 | R19: =CORREL('Return Data'!B8:B19,WorkBook!Q8:Q19) -> -0.27677851 | T19: =OFFSET('Return Data'!C19,-1,0) -> -0.0023 | U19: =CORREL('Return Data'!C8:C19,WorkBook!T8:T19) -> 0.29198934 | W19: =IF(D19<0,1,0) -> 1 | X19: =IF(E19<0,1,0) -> 1 | Y19: =IF(W19=1, IF(W18=0, Y18+1, Y18), Y18) -> 2 | Z19: =IF(X19=1, IF(X18=0, Z18+1, Z18), Z18) -> 2 | AB19: =CORREL(H8:H19,$F$2:$F$13) -> -0.15415862 | AC19: =CORREL(I8:I19,$F$2:$F$13) -> 0.45943882 | AE19: =IF($F19<0,$F19,"") | AF19: =IF($F19<0,'Return Data'!B19,"") | AG19: =IF($F19<0,'Return Data'!C19,"") | AI19: =AE57 -> -0.018091627 | AJ19: =AF57 -> -0.0914 | AK19: =AG57 -> -0.0174 | AP19: Hypothesis 3
A20: 42582 | B20: =B19*(1+'Return Data'!B20) -> 0.94520344 | C20: =C19*(1+'Return Data'!C20) -> 1.0346444 | D20: =B20/MAX($B$2:B20)-1 -> -0.17528432 | E20: =C20/MAX($C$2:C20)-1 -> -0.0036509479 | F20: 0.035609801 | H20: {=PRODUCT(1+'Return Data'!B9:B20)^(12/COUNT('Return Data'!B9:B20))-1} -> -0.15556909 | I20: {=PRODUCT(1+'Return Data'!C9:C20)^(12/COUNT('Return Data'!C9:C20))-1} -> 0.041363859 | J20: 0.08 | K20: =_xlfn.STDEV.S('Return Data'!B9:B20)*SQRT(12) -> 0.091389436 | L20: =_xlfn.STDEV.S('Return Data'!C9:C20)*SQRT(12) -> 0.049257644 | M20: =(H20-$P$5)/K20 -> -1.9211092 | N20: =(I20-$P$5)/L20 -> 0.43371662 | Q20: =OFFSET('Return Data'!B20,-1,0) -> -0.0298 | R20: =CORREL('Return Data'!B9:B20,WorkBook!Q9:Q20) -> -0.25757364 | T20: =OFFSET('Return Data'!C20,-1,0) -> 0.0107 | U20: =CORREL('Return Data'!C9:C20,WorkBook!T9:T20) -> 0.17938672 | W20: =IF(D20<0,1,0) -> 1 | X20: =IF(E20<0,1,0) -> 1 | Y20: =IF(W20=1, IF(W19=0, Y19+1, Y19), Y19) -> 2 | Z20: =IF(X20=1, IF(X19=0, Z19+1, Z19), Z19) -> 2 | AB20: =CORREL(H9:H20,$F$2:$F$13) -> -0.021898783 | AC20: =CORREL(I9:I20,$F$2:$F$13) -> -0.26619185 | AE20: =IF($F20<0,$F20,"") | AF20: =IF($F20<0,'Return Data'!B20,"") | AG20: =IF($F20<0,'Return Data'!C20,"") | AI20: =AE62 -> -0.0016280928 | AJ20: =AF62 -> -0.0199 | AK20: =AG62 -> 0.0256
A21: 42613 | B21: =B20*(1+'Return Data'!B21) -> 0.9556952 | C21: =C20*(1+'Return Data'!C21) -> 1.037231 | D21: =B21/MAX($B$2:B21)-1 -> -0.16612998 | E21: =C21/MAX($C$2:C21)-1 -> -0.0011600752 | F21: -0.0012192429 | H21: {=PRODUCT(1+'Return Data'!B10:B21)^(12/COUNT('Return Data'!B10:B21))-1} -> -0.095258987 | I21: {=PRODUCT(1+'Return Data'!C10:C21)^(12/COUNT('Return Data'!C10:C21))-1} -> 0.048581025 | J21: 0.08 | K21: =_xlfn.STDEV.S('Return Data'!B10:B21)*SQRT(12) -> 0.081396337 | L21: =_xlfn.STDEV.S('Return Data'!C10:C21)*SQRT(12) -> 0.048532164 | M21: =(H21-$P$5)/K21 -> -1.4160218 | N21: =(I21-$P$5)/L21 -> 0.58890893 | Q21: =OFFSET('Return Data'!B21,-1,0) -> 0.0029 | R21: =CORREL('Return Data'!B10:B21,WorkBook!Q10:Q21) -> -0.08416646 | T21: =OFFSET('Return Data'!C21,-1,0) -> 0.0132 | U21: =CORREL('Return Data'!C10:C21,WorkBook!T10:T21) -> 0.10814492 | W21: =IF(D21<0,1,0) -> 1 | X21: =IF(E21<0,1,0) -> 1 | Y21: =IF(W21=1, IF(W20=0, Y20+1, Y20), Y20) -> 2 | Z21: =IF(X21=1, IF(X20=0, Z20+1, Z20), Z20) -> 2 | AB21: =CORREL(H10:H21,$F$2:$F$13) -> 0.045809134 | AC21: =CORREL(I10:I21,$F$2:$F$13) -> 0.152597 | AE21: =IF($F21<0,$F21,"") -> -0.0012192429 | AF21: =IF($F21<0,'Return Data'!B21,"") -> 0.0111 | AG21: =IF($F21<0,'Return Data'!C21,"") -> 0.0025 | AI21: =AE63 -> -0.084110484 | AJ21: =AF63 -> -0.0622 | AK21: =AG63 -> -0.0105
A22: 42643 | B22: =B21*(1+'Return Data'!B22) -> 0.96104709 | C22: =C21*(1+'Return Data'!C22) -> 1.0418986 | D22: =B22/MAX($B$2:B22)-1 -> -0.16146031 | E22: =C22/MAX($C$2:C22)-1 -> 0 | F22: -0.0012344511 | H22: {=PRODUCT(1+'Return Data'!B11:B22)^(12/COUNT('Return Data'!B11:B22))-1} -> -0.089919414 | I22: {=PRODUCT(1+'Return Data'!C11:C22)^(12/COUNT('Return Data'!C11:C22))-1} -> 0.062972691 | J22: 0.08 | K22: =_xlfn.STDEV.S('Return Data'!B11:B22)*SQRT(12) -> 0.082218838 | L22: =_xlfn.STDEV.S('Return Data'!C11:C22)*SQRT(12) -> 0.046369543 | M22: =(H22-$P$5)/K22 -> -1.3369128 | N22: =(I22-$P$5)/L22 -> 0.92674389 | Q22: =OFFSET('Return Data'!B22,-1,0) -> 0.0111 | R22: =CORREL('Return Data'!B11:B22,WorkBook!Q11:Q22) -> 0.010011216 | T22: =OFFSET('Return Data'!C22,-1,0) -> 0.0025 | U22: =CORREL('Return Data'!C11:C22,WorkBook!T11:T22) -> 0.060677313 | W22: =IF(D22<0,1,0) -> 1 | X22: =IF(E22<0,1,0) -> 0 | Y22: =IF(W22=1, IF(W21=0, Y21+1, Y21), Y21) -> 2 | Z22: =IF(X22=1, IF(X21=0, Z21+1, Z21), Z21) -> 2 | AB22: =CORREL(H11:H22,$F$2:$F$13) -> -0.084047177 | AC22: =CORREL(I11:I22,$F$2:$F$13) -> 0.27539378 | AE22: =IF($F22<0,$F22,"") -> -0.0012344511 | AF22: =IF($F22<0,'Return Data'!B22,"") -> 0.0056 | AG22: =IF($F22<0,'Return Data'!C22,"") -> 0.0045 | AI22: =AE64 -> -0.12511928 | AJ22: =AF64 -> -0.1603 | AK22: =AG64 -> -0.1422 | AP22: (1) | AQ22: Static Correlation Vs S&P500
A23: 42674 | B23: =B22*(1+'Return Data'!B23) -> 1.0464842 | C23: =C22*(1+'Return Data'!C23) -> 1.0598192 | D23: =B23/MAX($B$2:B23)-1 -> -0.086914127 | E23: =C23/MAX($C$2:C23)-1 -> 0 | F23: -0.019425679 | H23: {=PRODUCT(1+'Return Data'!B12:B23)^(12/COUNT('Return Data'!B12:B23))-1} -> -0.035911323 | I23: {=PRODUCT(1+'Return Data'!C12:C23)^(12/COUNT('Return Data'!C12:C23))-1} -> 0.067696081 | J23: 0.08 | K23: =_xlfn.STDEV.S('Return Data'!B12:B23)*SQRT(12) -> 0.12328876 | L23: =_xlfn.STDEV.S('Return Data'!C12:C23)*SQRT(12) -> 0.047372825 | M23: =(H23-$P$5)/K23 -> -0.45349894 | N23: =(I23-$P$5)/L23 -> 1.0068237 | Q23: =OFFSET('Return Data'!B23,-1,0) -> 0.0056 | R23: =CORREL('Return Data'!B12:B23,WorkBook!Q12:Q23) -> 0.11550632 | T23: =OFFSET('Return Data'!C23,-1,0) -> 0.0045 | U23: =CORREL('Return Data'!C12:C23,WorkBook!T12:T23) -> 0.1114032 | W23: =IF(D23<0,1,0) -> 1 | X23: =IF(E23<0,1,0) -> 0 | Y23: =IF(W23=1, IF(W22=0, Y22+1, Y22), Y22) -> 2 | Z23: =IF(X23=1, IF(X22=0, Z22+1, Z22), Z22) -> 2 | AB23: =CORREL(H12:H23,$F$2:$F$13) -> 0.36285168 | AC23: =CORREL(I12:I23,$F$2:$F$13) -> -0.037779242 | AE23: =IF($F23<0,$F23,"") -> -0.019425679 | AF23: =IF($F23<0,'Return Data'!B23,"") -> 0.0889 | AG23: =IF($F23<0,'Return Data'!C23,"") -> 0.0172 | AI23: =AE70 -> -0.03922797 | AJ23: =AF70 -> -0.0269 | AK23: =AG70 -> 0.013 | AR23: Hedge Fund 1 | AS23: Hedge Fund 2
A24: 42704 | B24: =B23*(1+'Return Data'!B24) -> 1.0643791 | C24: =C23*(1+'Return Data'!C24) -> 1.0956411 | D24: =B24/MAX($B$2:B24)-1 -> -0.071300359 | E24: =C24/MAX($C$2:C24)-1 -> 0 | F24: 0.034174522 | H24: {=PRODUCT(1+'Return Data'!B13:B24)^(12/COUNT('Return Data'!B13:B24))-1} -> -0.029230182 | I24: {=PRODUCT(1+'Return Data'!C13:C24)^(12/COUNT('Return Data'!C13:C24))-1} -> 0.10777219 | J24: 0.08 | K24: =_xlfn.STDEV.S('Return Data'!B13:B24)*SQRT(12) -> 0.12426252 | L24: =_xlfn.STDEV.S('Return Data'!C13:C24)*SQRT(12) -> 0.053811008 | M24: =(H24-$P$5)/K24 -> -0.39617885 | N24: =(I24-$P$5)/L24 -> 1.6311196 | Q24: =OFFSET('Return Data'!B24,-1,0) -> 0.0889 | R24: =CORREL('Return Data'!B13:B24,WorkBook!Q13:Q24) -> 0.17659266 | T24: =OFFSET('Return Data'!C24,-1,0) -> 0.0172 | U24: =CORREL('Return Data'!C13:C24,WorkBook!T13:T24) -> 0.26468731 | W24: =IF(D24<0,1,0) -> 1 | X24: =IF(E24<0,1,0) -> 0 | Y24: =IF(W24=1, IF(W23=0, Y23+1, Y23), Y23) -> 2 | Z24: =IF(X24=1, IF(X23=0, Z23+1, Z23), Z23) -> 2 | AB24: =CORREL(H13:H24,$F$2:$F$13) -> 0.07807316 | AC24: =CORREL(I13:I24,$F$2:$F$13) -> 0.019767928 | AE24: =IF($F24<0,$F24,"") | AF24: =IF($F24<0,'Return Data'!B24,"") | AG24: =IF($F24<0,'Return Data'!C24,"") | AI24: =AE71 -> -0.027665786 | AJ24: =AF71 -> -0.0017 | AK24: =AG71 -> 0.0089 | AQ24: 15-20 | AR24: =CORREL('Return Data'!B2:B62,WorkBook!F2:$F$62) -> -0.017316749 | AS24: =CORREL('Return Data'!C2:C62,WorkBook!$F2:F$62) -> 0.56635004
A25: 42735 | B25: =B24*(1+'Return Data'!B25) -> 1.0880083 | C25: =C24*(1+'Return Data'!C25) -> 1.1036393 | D25: =B25/MAX($B$2:B25)-1 -> -0.050683227 | E25: =C25/MAX($C$2:C25)-1 -> 0 | F25: 0.018200762 | H25: {=PRODUCT(1+'Return Data'!B14:B25)^(12/COUNT('Return Data'!B14:B25))-1} -> 0.022273522 | I25: {=PRODUCT(1+'Return Data'!C14:C25)^(12/COUNT('Return Data'!C14:C25))-1} -> 0.12735798 | J25: 0.08 | K25: =_xlfn.STDEV.S('Return Data'!B14:B25)*SQRT(12) -> 0.1225305 | L25: =_xlfn.STDEV.S('Return Data'!C14:C25)*SQRT(12) -> 0.049811572 | M25: =(H25-$P$5)/K25 -> 0.018554742 | N25: =(I25-$P$5)/L25 -> 2.1552818 | Q25: =OFFSET('Return Data'!B25,-1,0) -> 0.0171 | R25: =CORREL('Return Data'!B14:B25,WorkBook!Q14:Q25) -> 0.23401605 | T25: =OFFSET('Return Data'!C25,-1,0) -> 0.0338 | U25: =CORREL('Return Data'!C14:C25,WorkBook!T14:T25) -> 0.14337151 | W25: =IF(D25<0,1,0) -> 1 | X25: =IF(E25<0,1,0) -> 0 | Y25: =IF(W25=1, IF(W24=0, Y24+1, Y24), Y24) -> 2 | Z25: =IF(X25=1, IF(X24=0, Z24+1, Z24), Z24) -> 2 | AB25: =CORREL(H14:H25,$F$2:$F$13) -> -0.0011404499 | AC25: =CORREL(I14:I25,$F$2:$F$13) -> -0.12145088 | AE25: =IF($F25<0,$F25,"") | AF25: =IF($F25<0,'Return Data'!B25,"") | AG25: =IF($F25<0,'Return Data'!C25,"") | AI25: =AE82 -> -0.047569169 | AJ25: =AF82 -> 0.0308 | AK25: =AG82 -> 0.0139 | AQ25: 20-25 | AR25: =CORREL('Return Data'!B63:B129,WorkBook!$F$63:$F$129) -> -0.044426563 | AS25: =CORREL('Return Data'!C63:C129,WorkBook!$F$63:$F$129) -> 0.56066114
A26: 42766 | B26: =B25*(1+'Return Data'!B26) -> 1.0776722 | C26: =C25*(1+'Return Data'!C26) -> 1.1315613 | D26: =B26/MAX($B$2:B26)-1 -> -0.059701736 | E26: =C26/MAX($C$2:C26)-1 -> 0 | F26: 0.017884358 | H26: {=PRODUCT(1+'Return Data'!B15:B26)^(12/COUNT('Return Data'!B15:B26))-1} -> 0.0055232606 | I26: {=PRODUCT(1+'Return Data'!C15:C26)^(12/COUNT('Return Data'!C15:C26))-1} -> 0.16355963 | J26: 0.08 | K26: =_xlfn.STDEV.S('Return Data'!B15:B26)*SQRT(12) -> 0.12296493 | L26: =_xlfn.STDEV.S('Return Data'!C15:C26)*SQRT(12) -> 0.048313173 | M26: =(H26-$P$5)/K26 -> -0.11773064 | N26: =(I26-$P$5)/L26 -> 2.9714386 | Q26: =OFFSET('Return Data'!B26,-1,0) -> 0.0222 | R26: =CORREL('Return Data'!B15:B26,WorkBook!Q15:Q26) -> 0.22998362 | T26: =OFFSET('Return Data'!C26,-1,0) -> 0.0073 | U26: =CORREL('Return Data'!C15:C26,WorkBook!T15:T26) -> -0.014028351 | W26: =IF(D26<0,1,0) -> 1 | X26: =IF(E26<0,1,0) -> 0 | Y26: =IF(W26=1, IF(W25=0, Y25+1, Y25), Y25) -> 2 | Z26: =IF(X26=1, IF(X25=0, Z25+1, Z25), Z25) -> 2 | AB26: =CORREL(H15:H26,$F$2:$F$13) -> 0.026093402 | AC26: =CORREL(I15:I26,$F$2:$F$13) -> 0.036389232 | AE26: =IF($F26<0,$F26,"") | AF26: =IF($F26<0,'Return Data'!B26,"") | AG26: =IF($F26<0,'Return Data'!C26,"") | AI26: =AE84 -> -0.0083337062 | AJ26: =AF84 -> -0.059 | AK26: =AG84 -> 0.0004 | AQ26: 15-25 | AR26: =CORREL('Return Data'!B2:B129,WorkBook!F2:$F$129) -> -0.034775269 | AS26: =CORREL('Return Data'!C2:C129,WorkBook!$F2:F$129) -> 0.55864169
A27: 42794 | B27: =B26*(1+'Return Data'!B27) -> 1.0909276 | C27: =C26*(1+'Return Data'!C27) -> 1.142198 | D27: =B27/MAX($B$2:B27)-1 -> -0.048136067 | E27: =C27/MAX($C$2:C27)-1 -> 0 | F27: 0.03719816 | H27: {=PRODUCT(1+'Return Data'!B16:B27)^(12/COUNT('Return Data'!B16:B27))-1} -> 0.080219884 | I27: {=PRODUCT(1+'Return Data'!C16:C27)^(12/COUNT('Return Data'!C16:C27))-1} -> 0.18816094 | J27: 0.08 | K27: =_xlfn.STDEV.S('Return Data'!B16:B27)*SQRT(12) -> 0.10512595 | L27: =_xlfn.STDEV.S('Return Data'!C16:C27)*SQRT(12) -> 0.040783241 | M27: =(H27-$P$5)/K27 -> 0.5728356 | N27: =(I27-$P$5)/L27 -> 4.1232853 | Q27: =OFFSET('Return Data'!B27,-1,0) -> -0.0095 | R27: =CORREL('Return Data'!B16:B27,WorkBook!Q16:Q27) -> 0.2876562 | T27: =OFFSET('Return Data'!C27,-1,0) -> 0.0253 | U27: =CORREL('Return Data'!C16:C27,WorkBook!T16:T27) -> -0.30142596 | W27: =IF(D27<0,1,0) -> 1 | X27: =IF(E27<0,1,0) -> 0 | Y27: =IF(W27=1, IF(W26=0, Y26+1, Y26), Y26) -> 2 | Z27: =IF(X27=1, IF(X26=0, Z26+1, Z26), Z26) -> 2 | AB27: =CORREL(H16:H27,$F$2:$F$13) -> 0.00089174024 | AC27: =CORREL(I16:I27,$F$2:$F$13) -> 0.045785427 | AE27: =IF($F27<0,$F27,"") | AF27: =IF($F27<0,'Return Data'!B27,"") | AG27: =IF($F27<0,'Return Data'!C27,"") | AI27: =AE86 -> -0.052585165 | AJ27: =AF86 -> 0.0432 | AK27: =AG86 -> -0.0216
A28: 42825 | B28: =B27*(1+'Return Data'!B28) -> 1.1104552 | C28: =C27*(1+'Return Data'!C28) -> 1.14117 | D28: =B28/MAX($B$2:B28)-1 -> -0.031097703 | E28: =C28/MAX($C$2:C28)-1 -> -0.0009 | F28: -0.00038919714 | H28: {=PRODUCT(1+'Return Data'!B17:B28)^(12/COUNT('Return Data'!B17:B28))-1} -> 0.11936864 | I28: {=PRODUCT(1+'Return Data'!C17:C28)^(12/COUNT('Return Data'!C17:C28))-1} -> 0.14772464 | J28: 0.08 | K28: =_xlfn.STDEV.S('Return Data'!B17:B28)*SQRT(12) -> 0.10203584 | L28: =_xlfn.STDEV.S('Return Data'!C17:C28)*SQRT(12) -> 0.037205278 | M28: =(H28-$P$5)/K28 -> 0.97386025 | N28: =(I28-$P$5)/L28 -> 3.4329709 | Q28: =OFFSET('Return Data'!B28,-1,0) -> 0.0123 | R28: =CORREL('Return Data'!B17:B28,WorkBook!Q17:Q28) -> 0.19152795 | T28: =OFFSET('Return Data'!C28,-1,0) -> 0.0094 | U28: =CORREL('Return Data'!C17:C28,WorkBook!T17:T28) -> 0.035509233 | W28: =IF(D28<0,1,0) -> 1 | X28: =IF(E28<0,1,0) -> 1 | Y28: =IF(W28=1, IF(W27=0, Y27+1, Y27), Y27) -> 2 | Z28: =IF(X28=1, IF(X27=0, Z27+1, Z27), Z27) -> 3 | AB28: =CORREL(H17:H28,$F$2:$F$13) -> -0.070120485 | AC28: =CORREL(I17:I28,$F$2:$F$13) -> 0.021374636 | AE28: =IF($F28<0,$F28,"") -> -0.00038919714 | AF28: =IF($F28<0,'Return Data'!B28,"") -> 0.0179 | AG28: =IF($F28<0,'Return Data'!C28,"") -> -0.0009 | AI28: =AE87 -> -0.031360492 | AJ28: =AF87 -> 0.0241 | AK28: =AG87 -> -0.0032
A29: 42855 | B29: =B28*(1+'Return Data'!B29) -> 1.0943536 | C29: =C28*(1+'Return Data'!C29) -> 1.1540653 | D29: =B29/MAX($B$2:B29)-1 -> -0.045146786 | E29: =C29/MAX($C$2:C29)-1 -> 0 | F29: 0.0090912087 | H29: {=PRODUCT(1+'Return Data'!B18:B29)^(12/COUNT('Return Data'!B18:B29))-1} -> 0.12565082 | I29: {=PRODUCT(1+'Return Data'!C18:C29)^(12/COUNT('Return Data'!C18:C29))-1} -> 0.13961112 | J29: 0.08 | K29: =_xlfn.STDEV.S('Return Data'!B18:B29)*SQRT(12) -> 0.10041744 | L29: =_xlfn.STDEV.S('Return Data'!C18:C29)*SQRT(12) -> 0.036437343 | M29: =(H29-$P$5)/K29 -> 1.0521162 | N29: =(I29-$P$5)/L29 -> 3.2826521 | Q29: =OFFSET('Return Data'!B29,-1,0) -> 0.0179 | R29: =CORREL('Return Data'!B18:B29,WorkBook!Q18:Q29) -> 0.092190658 | T29: =OFFSET('Return Data'!C29,-1,0) -> -0.0009 | U29: =CORREL('Return Data'!C18:C29,WorkBook!T18:T29) -> -0.083279035 | W29: =IF(D29<0,1,0) -> 1 | X29: =IF(E29<0,1,0) -> 0 | Y29: =IF(W29=1, IF(W28=0, Y28+1, Y28), Y28) -> 2 | Z29: =IF(X29=1, IF(X28=0, Z28+1, Z28), Z28) -> 3 | AB29: =CORREL(H18:H29,$F$2:$F$13) -> 0.017520887 | AC29: =CORREL(I18:I29,$F$2:$F$13) -> 0.11233999 | AE29: =IF($F29<0,$F29,"") | AF29: =IF($F29<0,'Return Data'!B29,"") | AG29: =IF($F29<0,'Return Data'!C29,"") | AI29: =AE89 -> -0.087956712 | AJ29: =AF89 -> 0.0766 | AK29: =AG89 -> -0.0016
A30: 42886 | B30: =B29*(1+'Return Data'!B30) -> 1.0714816 | C30: =C29*(1+'Return Data'!C30) -> 1.1650289 | D30: =B30/MAX($B$2:B30)-1 -> -0.065103218 | E30: =C30/MAX($C$2:C30)-1 -> 0 | F30: 0.011576251 | H30: {=PRODUCT(1+'Return Data'!B19:B30)^(12/COUNT('Return Data'!B19:B30))-1} -> 0.10300712 | I30: {=PRODUCT(1+'Return Data'!C19:C30)^(12/COUNT('Return Data'!C19:C30))-1} -> 0.15308953 | J30: 0.08 | K30: =_xlfn.STDEV.S('Return Data'!B19:B30)*SQRT(12) -> 0.10475556 | L30: =_xlfn.STDEV.S('Return Data'!C19:C30)*SQRT(12) -> 0.033533647 | M30: =(H30-$P$5)/K30 -> 0.79238871 | N30: =(I30-$P$5)/L30 -> 3.9688357 | Q30: =OFFSET('Return Data'!B30,-1,0) -> -0.0145 | R30: =CORREL('Return Data'!B19:B30,WorkBook!Q19:Q30) -> 0.13513588 | T30: =OFFSET('Return Data'!C30,-1,0) -> 0.0113 | U30: =CORREL('Return Data'!C19:C30,WorkBook!T19:T30) -> -0.0037408913 | W30: =IF(D30<0,1,0) -> 1 | X30: =IF(E30<0,1,0) -> 0 | Y30: =IF(W30=1, IF(W29=0, Y29+1, Y29), Y29) -> 2 | Z30: =IF(X30=1, IF(X29=0, Z29+1, Z29), Z29) -> 3 | AB30: =CORREL(H19:H30,$F$2:$F$13) -> 0.079838702 | AC30: =CORREL(I19:I30,$F$2:$F$13) -> -0.11870967 | AE30: =IF($F30<0,$F30,"") | AF30: =IF($F30<0,'Return Data'!B30,"") | AG30: =IF($F30<0,'Return Data'!C30,"") | AI30: =AE91 -> -0.08392 | AJ30: =AF91 -> 0.0425 | AK30: =AG91 -> -0.0337 | AP30: (2) | AQ30: Regressions Fund Returns Vs S&P 500 Returns
A31: 42916 | B31: =B30*(1+'Return Data'!B31) -> 1.0674099 | C31: =C30*(1+'Return Data'!C31) -> 1.1729511 | D31: =B31/MAX($B$2:B31)-1 -> -0.068655826 | E31: =C31/MAX($C$2:C31)-1 -> 0 | F31: 0.0048137752 | H31: {=PRODUCT(1+'Return Data'!B20:B31)^(12/COUNT('Return Data'!B20:B31))-1} -> 0.13256616 | I31: {=PRODUCT(1+'Return Data'!C20:C31)^(12/COUNT('Return Data'!C20:C31))-1} -> 0.14864009 | J31: 0.08 | K31: =_xlfn.STDEV.S('Return Data'!B20:B31)*SQRT(12) -> 0.097318685 | L31: =_xlfn.STDEV.S('Return Data'!C20:C31)*SQRT(12) -> 0.033921018 | M31: =(H31-$P$5)/K31 -> 1.1566758 | N31: =(I31-$P$5)/L31 -> 3.7923418 | Q31: =OFFSET('Return Data'!B31,-1,0) -> -0.0209 | R31: =CORREL('Return Data'!B20:B31,WorkBook!Q20:Q31) -> 0.13995143 | T31: =OFFSET('Return Data'!C31,-1,0) -> 0.0095 | U31: =CORREL('Return Data'!C20:C31,WorkBook!T20:T31) -> -0.0092531841 | W31: =IF(D31<0,1,0) -> 1 | X31: =IF(E31<0,1,0) -> 0 | Y31: =IF(W31=1, IF(W30=0, Y30+1, Y30), Y30) -> 2 | Z31: =IF(X31=1, IF(X30=0, Z30+1, Z30), Z30) -> 3 | AB31: =CORREL(H20:H31,$F$2:$F$13) -> 0.0057813451 | AC31: =CORREL(I20:I31,$F$2:$F$13) -> -0.19399146 | AE31: =IF($F31<0,$F31,"") | AF31: =IF($F31<0,'Return Data'!B31,"") | AG31: =IF($F31<0,'Return Data'!C31,"") | AI31: =AE93 -> -0.042440128 | AJ31: =AF93 -> 0.0341 | AK31: =AG93 -> 0.01
A32: 42947 | B32: =B31*(1+'Return Data'!B32) -> 1.0651684 | C32: =C31*(1+'Return Data'!C32) -> 1.1851498 | D32: =B32/MAX($B$2:B32)-1 -> -0.070611649 | E32: =C32/MAX($C$2:C32)-1 -> 0 | F32: 0.019348826 | H32: {=PRODUCT(1+'Return Data'!B21:B32)^(12/COUNT('Return Data'!B21:B32))-1} -> 0.12691971 | I32: {=PRODUCT(1+'Return Data'!C21:C32)^(12/COUNT('Return Data'!C21:C32))-1} -> 0.1454658 | J32: 0.08 | K32: =_xlfn.STDEV.S('Return Data'!B21:B32)*SQRT(12) -> 0.09788685 | L32: =_xlfn.STDEV.S('Return Data'!C21:C32)*SQRT(12) -> 0.033897747 | M32: =(H32-$P$5)/K32 -> 1.0922786 | N32: =(I32-$P$5)/L32 -> 3.701302 | Q32: =OFFSET('Return Data'!B32,-1,0) -> -0.0038 | R32: =CORREL('Return Data'!B21:B32,WorkBook!Q21:Q32) -> 0.13466994 | T32: =OFFSET('Return Data'!C32,-1,0) -> 0.0068 | U32: =CORREL('Return Data'!C21:C32,WorkBook!T21:T32) -> -0.0019520399 | W32: =IF(D32<0,1,0) -> 1 | X32: =IF(E32<0,1,0) -> 0 | Y32: =IF(W32=1, IF(W31=0, Y31+1, Y31), Y31) -> 2 | Z32: =IF(X32=1, IF(X31=0, Z31+1, Z31), Z31) -> 3 | AB32: =CORREL(H21:H32,$F$2:$F$13) -> -0.11315094 | AC32: =CORREL(I21:I32,$F$2:$F$13) -> 0.02665767 | AE32: =IF($F32<0,$F32,"") | AF32: =IF($F32<0,'Return Data'!B32,"") | AG32: =IF($F32<0,'Return Data'!C32,"") | AI32: =AE94 -> -0.093395672 | AJ32: =AF94 -> 0.0453 | AK32: =AG94 -> -0.017
A33: 42978 | B33: =B32*(1+'Return Data'!B33) -> 1.0700682 | C33: =C32*(1+'Return Data'!C33) -> 1.1947495 | D33: =B33/MAX($B$2:B33)-1 -> -0.066336462 | E33: =C33/MAX($C$2:C33)-1 -> 0 | F33: 0.00054643302 | H33: {=PRODUCT(1+'Return Data'!B22:B33)^(12/COUNT('Return Data'!B22:B33))-1} -> 0.11967514 | I33: {=PRODUCT(1+'Return Data'!C22:C33)^(12/COUNT('Return Data'!C22:C33))-1} -> 0.15186441 | J33: 0.08 | K33: =_xlfn.STDEV.S('Return Data'!B22:B33)*SQRT(12) -> 0.0980488 | L33: =_xlfn.STDEV.S('Return Data'!C22:C33)*SQRT(12) -> 0.032731789 | M33: =(H33-$P$5)/K33 -> 1.0165871 | N33: =(I33-$P$5)/L33 -> 4.0286345 | Q33: =OFFSET('Return Data'!B33,-1,0) -> -0.0021 | R33: =CORREL('Return Data'!B22:B33,WorkBook!Q22:Q33) -> 0.14245002 | T33: =OFFSET('Return Data'!C33,-1,0) -> 0.0104 | U33: =CORREL('Return Data'!C22:C33,WorkBook!T22:T33) -> 0.016903904 | W33: =IF(D33<0,1,0) -> 1 | X33: =IF(E33<0,1,0) -> 0 | Y33: =IF(W33=1, IF(W32=0, Y32+1, Y32), Y32) -> 2 | Z33: =IF(X33=1, IF(X32=0, Z32+1, Z32), Z32) -> 3 | AB33: =CORREL(H22:H33,$F$2:$F$13) -> 0.018903043 | AC33: =CORREL(I22:I33,$F$2:$F$13) -> -0.09223578 | AE33: =IF($F33<0,$F33,"") | AF33: =IF($F33<0,'Return Data'!B33,"") | AG33: =IF($F33<0,'Return Data'!C33,"") | AI33: =AE97 -> -0.058971474 | AJ33: =AF97 -> 0.0134 | AK33: =AG97 -> 0.0149
A34: 43008 | B34: =B33*(1+'Return Data'!B34) -> 1.0740274 | C34: =C33*(1+'Return Data'!C34) -> 1.2301141 | D34: =B34/MAX($B$2:B34)-1 -> -0.062881907 | E34: =C34/MAX($C$2:C34)-1 -> 0 | F34: 0.019302979 | H34: {=PRODUCT(1+'Return Data'!B23:B34)^(12/COUNT('Return Data'!B23:B34))-1} -> 0.11755961 | I34: {=PRODUCT(1+'Return Data'!C23:C34)^(12/COUNT('Return Data'!C23:C34))-1} -> 0.18064669 | J34: 0.08 | K34: =_xlfn.STDEV.S('Return Data'!B23:B34)*SQRT(12) -> 0.09815629 | L34: =_xlfn.STDEV.S('Return Data'!C23:C34)*SQRT(12) -> 0.03600813 | M34: =(H34-$P$5)/K34 -> 0.99392111 | N34: =(I34-$P$5)/L34 -> 4.4614005 | Q34: =OFFSET('Return Data'!B34,-1,0) -> 0.0046 | R34: =CORREL('Return Data'!B23:B34,WorkBook!Q23:Q34) -> 0.14628928 | T34: =OFFSET('Return Data'!C34,-1,0) -> 0.0081 | U34: =CORREL('Return Data'!C23:C34,WorkBook!T23:T34) -> -0.11048912 | W34: =IF(D34<0,1,0) -> 1 | X34: =IF(E34<0,1,0) -> 0 | Y34: =IF(W34=1, IF(W33=0, Y33+1, Y33), Y33) -> 2 | Z34: =IF(X34=1, IF(X33=0, Z33+1, Z33), Z33) -> 3 | AB34: =CORREL(H23:H34,$F$2:$F$13) -> -0.051253885 | AC34: =CORREL(I23:I34,$F$2:$F$13) -> -0.0032125303 | AE34: =IF($F34<0,$F34,"") | AF34: =IF($F34<0,'Return Data'!B34,"") | AG34: =IF($F34<0,'Return Data'!C34,"") | AI34: =AE99 -> -0.026112494 | AJ34: =AF99 -> 0.0568 | AK34: =AG99 -> -0.0112 | AQ34: SUMMARY OUTPUT HF1
A35: 43039 | B35: =B34*(1+'Return Data'!B35) -> 1.1012003 | C35: =C34*(1+'Return Data'!C35) -> 1.2411851 | D35: =B35/MAX($B$2:B35)-1 -> -0.03917282 | E35: =C35/MAX($C$2:C35)-1 -> 0 | F35: 0.022188135 | H35: {=PRODUCT(1+'Return Data'!B24:B35)^(12/COUNT('Return Data'!B24:B35))-1} -> 0.052285671 | I35: {=PRODUCT(1+'Return Data'!C24:C35)^(12/COUNT('Return Data'!C24:C35))-1} -> 0.17112909 | J35: 0.08 | K35: =_xlfn.STDEV.S('Return Data'!B24:B35)*SQRT(12) -> 0.051804975 | L35: =_xlfn.STDEV.S('Return Data'!C24:C35)*SQRT(12) -> 0.036142445 | M35: =(H35-$P$5)/K35 -> 0.62321564 | N35: =(I35-$P$5)/L35 -> 4.1814849 | Q35: =OFFSET('Return Data'!B35,-1,0) -> 0.0037 | R35: =CORREL('Return Data'!B24:B35,WorkBook!Q24:Q35) -> 0.32587265 | T35: =OFFSET('Return Data'!C35,-1,0) -> 0.0296 | U35: =CORREL('Return Data'!C24:C35,WorkBook!T24:T35) -> -0.13972689 | W35: =IF(D35<0,1,0) -> 1 | X35: =IF(E35<0,1,0) -> 0 | Y35: =IF(W35=1, IF(W34=0, Y34+1, Y34), Y34) -> 2 | Z35: =IF(X35=1, IF(X34=0, Z34+1, Z34), Z34) -> 3 | AB35: =CORREL(H24:H35,$F$2:$F$13) -> 0.030965138 | AC35: =CORREL(I24:I35,$F$2:$F$13) -> 0.045351897 | AE35: =IF($F35<0,$F35,"") | AF35: =IF($F35<0,'Return Data'!B35,"") | AG35: =IF($F35<0,'Return Data'!C35,"") | AI35: =AE105 -> -0.01771639 | AJ35: =AF105 -> 0.0302 | AK35: =AG105 -> -0.0111
A36: 43069 | B36: =B35*(1+'Return Data'!B36) -> 1.105495 | C36: =C35*(1+'Return Data'!C36) -> 1.2540934 | D36: =B36/MAX($B$2:B36)-1 -> -0.035425594 | E36: =C36/MAX($C$2:C36)-1 -> 0 | F36: 0.028082628 | H36: {=PRODUCT(1+'Return Data'!B25:B36)^(12/COUNT('Return Data'!B25:B36))-1} -> 0.038629029 | I36: {=PRODUCT(1+'Return Data'!C25:C36)^(12/COUNT('Return Data'!C25:C36))-1} -> 0.14462065 | J36: 0.08 | K36: =_xlfn.STDEV.S('Return Data'!B25:B36)*SQRT(12) -> 0.049910274 | L36: =_xlfn.STDEV.S('Return Data'!C25:C36)*SQRT(12) -> 0.028411585 | M36: =(H36-$P$5)/K36 -> 0.37325038 | N36: =(I36-$P$5)/L36 -> 4.3862619 | Q36: =OFFSET('Return Data'!B36,-1,0) -> 0.0253 | R36: =CORREL('Return Data'!B25:B36,WorkBook!Q25:Q36) -> 0.18233957 | T36: =OFFSET('Return Data'!C36,-1,0) -> 0.009 | U36: =CORREL('Return Data'!C25:C36,WorkBook!T25:T36) -> -0.24877505 | W36: =IF(D36<0,1,0) -> 1 | X36: =IF(E36<0,1,0) -> 0 | Y36: =IF(W36=1, IF(W35=0, Y35+1, Y35), Y35) -> 2 | Z36: =IF(X36=1, IF(X35=0, Z35+1, Z35), Z35) -> 3 | AB36: =CORREL(H25:H36,$F$2:$F$13) -> -0.052039923 | AC36: =CORREL(I25:I36,$F$2:$F$13) -> 0.45149186 | AE36: =IF($F36<0,$F36,"") | AF36: =IF($F36<0,'Return Data'!B36,"") | AG36: =IF($F36<0,'Return Data'!C36,"") | AI36: =AE106 -> -0.048719367 | AJ36: =AF106 -> 0.0469 | AK36: =AG106 -> -0.0219 | AQ36: Regression Statistics
A37: 43100 | B37: =B36*(1+'Return Data'!B37) -> 1.1112436 | C37: =C36*(1+'Return Data'!C37) -> 1.2696442 | D37: =B37/MAX($B$2:B37)-1 -> -0.030409807 | E37: =C37/MAX($C$2:C37)-1 -> 0 | F37: 0.0098316306 | H37: {=PRODUCT(1+'Return Data'!B26:B37)^(12/COUNT('Return Data'!B26:B37))-1} -> 0.021355801 | I37: {=PRODUCT(1+'Return Data'!C26:C37)^(12/COUNT('Return Data'!C26:C37))-1} -> 0.15041591 | J37: 0.08 | K37: =_xlfn.STDEV.S('Return Data'!B26:B37)*SQRT(12) -> 0.045579292 | L37: =_xlfn.STDEV.S('Return Data'!C26:C37)*SQRT(12) -> 0.028074236 | M37: =(H37-$P$5)/K37 -> 0.029745981 | N37: =(I37-$P$5)/L37 -> 4.6453949 | Q37: =OFFSET('Return Data'!B37,-1,0) -> 0.0039 | R37: =CORREL('Return Data'!B26:B37,WorkBook!Q26:Q37) -> 0.082113205 | T37: =OFFSET('Return Data'!C37,-1,0) -> 0.0104 | U37: =CORREL('Return Data'!C26:C37,WorkBook!T26:T37) -> -0.1972813 | W37: =IF(D37<0,1,0) -> 1 | X37: =IF(E37<0,1,0) -> 0 | Y37: =IF(W37=1, IF(W36=0, Y36+1, Y36), Y36) -> 2 | Z37: =IF(X37=1, IF(X36=0, Z36+1, Z36), Z36) -> 3 | AB37: =CORREL(H26:H37,$F$2:$F$13) -> -0.13563866 | AC37: =CORREL(I26:I37,$F$2:$F$13) -> 0.3573696 | AE37: =IF($F37<0,$F37,"") | AF37: =IF($F37<0,'Return Data'!B37,"") | AG37: =IF($F37<0,'Return Data'!C37,"") | AI37: =AE107 -> -0.021979689 | AJ37: =AF107 -> 0.0358 | AK37: =AG107 -> 0.0139 | AQ37: Multiple R | AR37: 0.022305845
A38: 43131 | B38: =B37*(1+'Return Data'!B38) -> 1.1586937 | C38: =C37*(1+'Return Data'!C38) -> 1.2965606 | D38: =B38/MAX($B$2:B38)-1 -> 0 | E38: =C38/MAX($C$2:C38)-1 -> 0 | F38: 0.056178704 | H38: {=PRODUCT(1+'Return Data'!B27:B38)^(12/COUNT('Return Data'!B27:B38))-1} -> 0.075181922 | I38: {=PRODUCT(1+'Return Data'!C27:C38)^(12/COUNT('Return Data'!C27:C38))-1} -> 0.1458156 | J38: 0.08 | K38: =_xlfn.STDEV.S('Return Data'!B27:B38)*SQRT(12) -> 0.059250309 | L38: =_xlfn.STDEV.S('Return Data'!C27:C38)*SQRT(12) -> 0.026153116 | M38: =(H38-$P$5)/K38 -> 0.9313356 | N38: =(I38-$P$5)/L38 -> 4.8107307 | Q38: =OFFSET('Return Data'!B38,-1,0) -> 0.0052 | R38: =CORREL('Return Data'!B27:B38,WorkBook!Q27:Q38) -> 0.21786946 | T38: =OFFSET('Return Data'!C38,-1,0) -> 0.0124 | U38: =CORREL('Return Data'!C27:C38,WorkBook!T27:T38) -> -0.11563897 | W38: =IF(D38<0,1,0) -> 0 | X38: =IF(E38<0,1,0) -> 0 | Y38: =IF(W38=1, IF(W37=0, Y37+1, Y37), Y37) -> 2 | Z38: =IF(X38=1, IF(X37=0, Z37+1, Z37), Z37) -> 3 | AB38: =CORREL(H27:H38,$F$2:$F$13) -> -0.18904258 | AC38: =CORREL(I27:I38,$F$2:$F$13) -> -0.56970345 | AE38: =IF($F38<0,$F38,"") | AF38: =IF($F38<0,'Return Data'!B38,"") | AG38: =IF($F38<0,'Return Data'!C38,"") | AI38: =AE113 -> -0.041615072 | AJ38: =AF113 -> 0.0552 | AK38: =AG113 -> 0.0051 | AQ38: R Square | AR38: 0.00049755071
A39: 43159 | B39: =B38*(1+'Return Data'!B39) -> 1.1798978 | C39: =C38*(1+'Return Data'!C39) -> 1.3013579 | D39: =B39/MAX($B$2:B39)-1 -> 0 | E39: =C39/MAX($C$2:C39)-1 -> 0 | F39: -0.038947372 | H39: {=PRODUCT(1+'Return Data'!B28:B39)^(12/COUNT('Return Data'!B28:B39))-1} -> 0.081554629 | I39: {=PRODUCT(1+'Return Data'!C28:C39)^(12/COUNT('Return Data'!C28:C39))-1} -> 0.13934527 | J39: 0.08 | K39: =_xlfn.STDEV.S('Return Data'!B28:B39)*SQRT(12) -> 0.060220949 | L39: =_xlfn.STDEV.S('Return Data'!C28:C39)*SQRT(12) -> 0.027235321 | M39: =(H39-$P$5)/K39 -> 1.0221464 | N39: =(I39-$P$5)/L39 -> 4.3820033 | Q39: =OFFSET('Return Data'!B39,-1,0) -> 0.0427 | R39: =CORREL('Return Data'!B28:B39,WorkBook!Q28:Q39) -> 0.32935671 | T39: =OFFSET('Return Data'!C39,-1,0) -> 0.0212 | U39: =CORREL('Return Data'!C28:C39,WorkBook!T28:T39) -> -0.19169454 | W39: =IF(D39<0,1,0) -> 0 | X39: =IF(E39<0,1,0) -> 0 | Y39: =IF(W39=1, IF(W38=0, Y38+1, Y38), Y38) -> 2 | Z39: =IF(X39=1, IF(X38=0, Z38+1, Z38), Z38) -> 3 | AB39: =CORREL(H28:H39,$F$2:$F$13) -> -0.022910295 | AC39: =CORREL(I28:I39,$F$2:$F$13) -> -0.18764984 | AE39: =IF($F39<0,$F39,"") -> -0.038947372 | AF39: =IF($F39<0,'Return Data'!B39,"") -> 0.0183 | AG39: =IF($F39<0,'Return Data'!C39,"") -> 0.0037 | AI39: =AE119 -> -0.0098967433 | AJ39: =AF119 -> 0.0332 | AK39: =AG119 -> 0.0014 | AQ39: Adjusted R Square | AR39: -0.0074984689
A40: 43190 | B40: =B39*(1+'Return Data'!B40) -> 1.1605474 | C40: =C39*(1+'Return Data'!C40) -> 1.2788444 | D40: =B40/MAX($B$2:B40)-1 -> -0.0164 | E40: =C40/MAX($C$2:C40)-1 -> -0.0173 | F40: -0.026884499 | H40: {=PRODUCT(1+'Return Data'!B29:B40)^(12/COUNT('Return Data'!B29:B40))-1} -> 0.04510967 | I40: {=PRODUCT(1+'Return Data'!C29:C40)^(12/COUNT('Return Data'!C29:C40))-1} -> 0.12064317 | J40: 0.08 | K40: =_xlfn.STDEV.S('Return Data'!B29:B40)*SQRT(12) -> 0.062962384 | L40: =_xlfn.STDEV.S('Return Data'!C29:C40)*SQRT(12) -> 0.037881862 | M40: =(H40-$P$5)/K40 -> 0.39880431 | N40: =(I40-$P$5)/L40 -> 2.6567642 | Q40: =OFFSET('Return Data'!B40,-1,0) -> 0.0183 | R40: =CORREL('Return Data'!B29:B40,WorkBook!Q29:Q40) -> 0.21472996 | T40: =OFFSET('Return Data'!C40,-1,0) -> 0.0037 | U40: =CORREL('Return Data'!C29:C40,WorkBook!T29:T40) -> 0.064991793 | W40: =IF(D40<0,1,0) -> 1 | X40: =IF(E40<0,1,0) -> 1 | Y40: =IF(W40=1, IF(W39=0, Y39+1, Y39), Y39) -> 3 | Z40: =IF(X40=1, IF(X39=0, Z39+1, Z39), Z39) -> 4 | AB40: =CORREL(H29:H40,$F$2:$F$13) -> 0.16040609 | AC40: =CORREL(I29:I40,$F$2:$F$13) -> 0.11471008 | AE40: =IF($F40<0,$F40,"") -> -0.026884499 | AF40: =IF($F40<0,'Return Data'!B40,"") -> -0.0164 | AG40: =IF($F40<0,'Return Data'!C40,"") -> -0.0173 | AI40: =AE121 -> -0.024990137 | AJ40: =AF121 -> 0.034 | AK40: =AG121 -> 0.0199 | AQ40: Standard Error | AR40: 0.040159432
...

Sheet Objective 1 Evaluation

Sheet Objective 2 Evaluation
B38: Hypothesis 2: Capital Preservation
E41: =WorkBook!AR6 -> Hedge Fund 1 | F41: =WorkBook!AS6 -> Hedge Fund 2
C42: =WorkBook!AP7 -> Depth of worst loss | D42: =WorkBook!AQ7 -> Maximum Drawdown (MDD) | E42: =WorkBook!AR7 -> -0.233163 | F42: =WorkBook!AS7 -> -0.1512069
D43: =WorkBook!AQ8 -> Average Annualized Return | E43: =WorkBook!AR8 -> 0.054434931 | F43: =WorkBook!AS8 -> 0.096126043
C44: =WorkBook!AP9 -> Time underwater | D44: =WorkBook!AQ9 -> Average Drawdown Duration | E44: =WorkBook!AR9 -> 8.8333333 | F44: =WorkBook!AS9 -> 5.2307692
C45: =WorkBook!AP10 -> Recovery Efficiency | D45: =WorkBook!AQ10 -> MAR Ratio ( Return / Max Drawdown ) | E45: =WorkBook!AR10 -> 0.23346299 | F45: =WorkBook!AS10 -> 0.63572524
C46: =WorkBook!AP11 -> How deep and persistent drawdowns are | D46: =WorkBook!AQ11 -> Ulcer Index (UI) | E46: =WorkBook!AR11 -> 0.094449932 | F46: =WorkBook!AS11 -> 0.03242902

Sheet Objective 3 Evaluation
A66: Test 1 | G66: Test 2 | R66: Test 3
A67: Static Correlation Vs S&P500 | G67: Regressions Fund Returns Vs S&P 500 Returns
B68: Hedge Fund 1 | C68: Hedge Fund 2 | R68: Crisis Behavior Test | S68: Low or negative correlation during down months -> true crisis diversification.
A69: 15-20 | B69: -0.017316749 | C69: 0.56635004 | S69: HF1 | T69: HF2
A70: 20-25 | B70: -0.044426563 | C70: 0.56066114 | F70: a. | G70: SUMMARY OUTPUT HF1 | R70: Down-Market Beta | S70: 0.15003256 | T70: 0.44315784
A71: 15-25 | B71: -0.034775269 | C71: 0.55864169
G72: Regression Statistics | Q72: a. | R72: SUMMARY OUTPUT Down Market Beta HF1
G73: Multiple R | H73: 0.022305845
G74: R Square | H74: 0.00049755071 | R74: Regression Statistics
G75: Adjusted R Square | H75: -0.0074984689 | R75: Multiple R | S75: 0.09306632
G76: Standard Error | H76: 0.040159432 | R76: R Square | S76: 0.00866134
G77: Observations | H77: 127 | R77: Adjusted R Square | S77: -0.0167576
A78: Test 4 | R78: Standard Error | S78: 0.049483505
A79: Structural Contribution (Portfolio Diversification Benefit) | G79: ANOVA | R79: Observations | S79: 41
H80: df | I80: SS | J80: MS | K80: F | L80: Significance F
B81: HedgeFund 1 | C81: HedgeFund 2 | D81: S&P 500 | G81: Regression | H81: 1 | I81: 0.00010035491 | J81: 0.00010035491 | K81: 0.062224799 | L81: 0.80342294 | R81: ANOVA
A82: Standard Deviation | B82: 0.040174395 | C82: 0.02141346 | D82: 0.04361497 | G82: Residual | H82: 125 | I82: 0.2015975 | J82: 0.00161278 | S82: df | T82: SS | U82: MS | V82: F | W82: Significance F
A83: Diversification Benefit | B83: 0.30466933 | C83: 0.10275771 | G83: Total | H83: 126 | I83: 0.20169786 | R83: Regression | S83: 1 | T83: 0.00083435 | U83: 0.00083435 | V83: 0.34074356 | W83: 0.56276142
R84: Residual | S84: 39 | T84: 0.09549607 | U84: 0.00244862
H85: Coefficients | I85: Standard Error | J85: t Stat | K85: P-value | L85: Lower 95% | M85: Upper 95% | N85: Lower 95.0% | O85: Upper 95.0% | R85: Total | S85: 40 | T85: 0.09633042
G86: Intercept | H86: 0.0054921676 | I86: 0.0036604711 | J86: 1.5003991 | K86: 0.13603269 | L86: -0.001752359 | M86: 0.012736694 | N86: -0.001752359 | O86: 0.012736694
G87: -0.031 | H87: -0.020372261 | I87: 0.081669045 | J87: -0.24944899 | K87: 0.80342294 | L87: -0.18200544 | M87: 0.14126091 | N87: -0.18200544 | O87: 0.14126091 | S87: Coefficients | T87: Standard Error | U87: t Stat | V87: P-value | W87: Lower 95% | X87: Upper 95% | Y87: Lower 95.0% | Z87: Upper 95.0%
R88: Intercept | S88: 0.015339192 | T88: 0.01260102 | U88: 1.2172974 | V88: 0.23080578 | W88: -0.010148782 | X88: 0.040827165 | Y88: -0.01014878 | Z88: 0.04082717
R89: -0.031 | S89: 0.15003256 | T89: 0.25702283 | U89: 0.58373243 | V89: 0.56276142 | W89: -0.36984518 | X89: 0.66991031 | Y89: -0.36984518 | Z89: 0.66991031
F91: b. | G91: SUMMARY OUTPUT HF2
G93: Regression Statistics
G94: Multiple R | H94: 0.55647102
G95: R Square | H95: 0.30966 | Q95: b. | R95: SUMMARY OUTPUT Down Market Beta HF2
G96: Adjusted R Square | H96: 0.30413728
G97: Standard Error | H97: 0.017969163 | R97: Regression Statistics
G98: Observations | H98: 127 | R98: Multiple R | S98: 0.51145407
R99: R Square | S99: 0.26158526
G100: ANOVA | R100: Adjusted R Square | S100: 0.24265155
H101: df | I101: SS | J101: MS | K101: F | L101: Significance F | R101: Standard Error | S101: 0.022954002
G102: Regression | H102: 1 | I102: 0.018104551 | J102: 0.018104551 | K102: 56.070197 | L102: 1.0997503e-11 | R102: Observations | S102: 41
G103: Residual | H103: 125 | I103: 0.040361351 | J103: 0.00032289081
G104: Total | H104: 126 | I104: 0.058465902 | R104: ANOVA
S105: df | T105: SS | U105: MS | V105: F | W105: Significance F
H106: Coefficients | I106: Standard Error | J106: t Stat | K106: P-value | L106: Lower 95% | M106: Upper 95% | N106: Lower 95.0% | O106: Upper 95.0% | R106: Regression | S106: 1 | T106: 0.0072793796 | U106: 0.0072793796 | V106: 13.815847 | W106: 0.00063178212
G107: Intercept | H107: 0.0046141278 | I107: 0.0016378618 | J107: 2.8171655 | K107: 0.0056330464 | L107: 0.001372596 | M107: 0.0078556596 | N107: 0.001372596 | O107: 0.0078556596 | R107: Residual | S107: 39 | T107: 0.020548563 | U107: 0.00052688623
...
